<?xml version="1.0" encoding= "UTF-8" ?>

<robot name="Asimo_E1" xmlns:xacro="http://www.ros.org/wiki/xacro">
  
 <xacro:property name="PI" value="3.1415926535897931"/>



<link name="body">
  <visual>
    <origin rpy="0 0 0" xyz="0 0 3.4"/>
    <geometry>
      <box size="1 1.5 1"/>
    </geometry>
    <material name="white">
      <color rgba="1 1 1 1"/>
    </material>
  </visual>

  <collision>
      <geometry>
          <box size="1 1.5 1"/>
      </geometry>
  </collision>
  <inertial>
      <mass value="1.0" />
      <inertia ixx="0.0741666666667" ixy="0.0" ixz="0.0" iyy="0.0585416666667" iyz="0.0" izz="0.0260416666667"/>
  </inertial>
</link>

<link name="hip_l">
  <visual>
    <origin rpy="1.57075 0 1.57075" xyz="0 -0.5 2.7"/>
    <geometry>
      <cylinder length="0.5" radius="0.2"/>
    </geometry>
  </visual>

  <collision>
        <geometry>
            <cylinder length="0.5" radius="0.2"/>
        </geometry>
    </collision>
    <inertial>
        <mass value="1.0" />
        <inertia ixx="0.0741666666667" ixy="0.0" ixz="0.0" iyy="0.0585416666667" iyz="0.0" izz="0.0260416666667"/>
    </inertial>

</link>

<link name="hip_r">
  <visual>
    <origin rpy="1.57075 0 1.57075" xyz="0 0.5 2.7"/>
    <geometry>
      <cylinder length="0.5" radius="0.2"/>
    </geometry>
  </visual>
  <collision>
        <geometry>
            <cylinder length="0.5" radius="0.2"/>
        </geometry>
    </collision>
    <inertial>
        <mass value="1.0" />
        <inertia ixx="0.0741666666667" ixy="0.0" ixz="0.0" iyy="0.0585416666667" iyz="0.0" izz="0.0260416666667"/>
    </inertial>
</link>

<joint name="body_hip_l" type="revolute">
  <parent link="body"/>
  <child link="hip_l"/>
  <limit lower="-1.57" upper="1.57" effort="10" velocity="3"/>
</joint>

<joint name="body_hip_r" type="revolute">
  <parent link="body"/>
  <child link="hip_r"/>
  <origin xyz="0 0 0" rpy="0 0 0"/>
  <limit lower="-1.57" upper="1.57" effort="10" velocity="3"/>
</joint>

 <transmission name="tran1">
    <type>transmission_interface/SimpleTransmission</type>
    <joint name="body_hip_l">
      <hardwareInterface>hardware_interface/EffortJointInterface</hardwareInterface>
    </joint>
    <actuator name="motor1">
      <hardwareInterface>hardware_interface/EffortJointInterface</hardwareInterface>
      <mechanicalReduction>1</mechanicalReduction>
    </actuator>
  </transmission>

   <transmission name="tran2">
    <type>transmission_interface/SimpleTransmission</type>
    <joint name="body_hip_r">
      <hardwareInterface>hardware_interface/EffortJointInterface</hardwareInterface>
    </joint>
    <actuator name="motor2">
      <hardwareInterface>hardware_interface/EffortJointInterface</hardwareInterface>
      <mechanicalReduction>1</mechanicalReduction>
    </actuator>
  </transmission>


<gazebo>
    <plugin name="gazebo_ros_control" filename="libgazebo_ros_control.so">
      <robotNamespace>/Asimo_E1</robotNamespace> 
    </plugin>
</gazebo>



</robot>